
***********************************************************
Thu Jul 30 20:09:22 2015: engine server start
————————————————————————————————————————————————————

***********************************************************
Thu Jul 30 20:57:54 2015: engine server start
————————————————————————————————————————————————————

***********************************************************
Thu Jul 30 21:49:08 2015: engine server start
————————————————————————————————————————————————————

***********************************************************
Thu Jul 30 23:51:56 2015: engine server start
————————————————————————————————————————————————————

***********************************************************
Thu Jul 30 23:57:52 2015: engine server start
————————————————————————————————————————————————————

***********************************************************
Fri Jul 31 10:39:51 2015: engine server start
————————————————————————————————————————————————————
Fri Jul 31 11:30:59 2015  Fri Jul 31 11:30:59 2015  Error: Cannot connect to database default :
[Errno 111] Connection refused in engine_start  task_id: 238: 
Traceback (most recent call last):
  File "FiltrateEngine.py", line 28, in engine_start
    self.write_process_pid, self.remove_process_pid)
  File "/home/zxy/phishing_check/filtrate/filtrate_start.py", line 38, in __init__
    mongo_password)
  File "../server_base/mongo_handle.py", line 36, in __init__
    username=mongo_username, password=mongo_password)
  File "build/bdist.linux-i686/egg/mongoengine/connection.py", line 164, in connect
    return get_connection(alias)
  File "build/bdist.linux-i686/egg/mongoengine/connection.py", line 126, in get_connection
    raise ConnectionError("Cannot connect to database %s :\n%s" % (alias, e))
ConnectionError: Cannot connect to database default :
[Errno 111] Connection refused

***********************************************************
Fri Jul 31 11:44:26 2015: engine server start
————————————————————————————————————————————————————
Fri Jul 31 14:26:34 2015  Fri Jul 31 14:26:34 2015  Mongo Error ()  expand_gray_list, objectID: 55bb1156351ff517d9216f4
Fri Jul 31 14:38:43 2015  Fri Jul 31 14:38:43 2015  Mongo Error ()  expand_gray_list, objectID: 55bb1156351ff517d9216f4
Fri Jul 31 14:40:39 2015  Fri Jul 31 14:40:39 2015  Mongo Error ()  expand_gray_list, objectID: 55bb1156351ff517d9216f4
Fri Jul 31 15:34:12 2015  Fri Jul 31 15:34:12 2015  Mysql Error 1317: Query execution was interrupted sql: update server_live set time='2015-07-31 15:34' where ip='192.168.174.128' and port='23464'
Traceback (most recent call last):
  File "../server_base/mysql_handle.py", line 286, in require_post
    self.cur.execute(sql)
  File "/usr/lib/python2.7/dist-packages/MySQLdb/cursors.py", line 174, in execute
    self.errorhandler(self, exc, value)
  File "/usr/lib/python2.7/dist-packages/MySQLdb/connections.py", line 36, in defaulterrorhandler
    raise errorclass, errorvalue
OperationalError: (1317, 'Query execution was interrupted')
Fri Jul 31 16:41:47 2015  Fri Jul 31 16:41:47 2015  Mysql Error 2003: Can't connect to MySQL server on '192.168.65.148' (22) sql: 
Traceback (most recent call last):
  File "../server_base/mysql_handle.py", line 74, in connect_MySQL
    self.mysql_db, charset='utf8')
  File "/usr/lib/python2.7/dist-packages/MySQLdb/__init__.py", line 81, in Connect
    return Connection(*args, **kwargs)
  File "/usr/lib/python2.7/dist-packages/MySQLdb/connections.py", line 187, in __init__
    super(Connection, self).__init__(*args, **kwargs2)
OperationalError: (2003, "Can't connect to MySQL server on '192.168.65.148' (22)")
Fri Jul 31 16:40:10 2015  Fri Jul 31 16:40:10 2015  Mysql Error 2003: Can't connect to MySQL server on '192.168.65.148' (111) sql: 
Traceback (most recent call last):
  File "../server_base/mysql_handle.py", line 74, in connect_MySQL
    self.mysql_db, charset='utf8')
  File "/usr/lib/python2.7/dist-packages/MySQLdb/__init__.py", line 81, in Connect
    return Connection(*args, **kwargs)
  File "/usr/lib/python2.7/dist-packages/MySQLdb/connections.py", line 187, in __init__
    super(Connection, self).__init__(*args, **kwargs2)
OperationalError: (2003, "Can't connect to MySQL server on '192.168.65.148' (111)")
Fri Jul 31 16:41:01 2015  Fri Jul 31 16:41:01 2015  Mysql Error 2003: Can't connect to MySQL server on '192.168.65.148' (111) sql: 
Traceback (most recent call last):
  File "../server_base/mysql_handle.py", line 74, in connect_MySQL
    self.mysql_db, charset='utf8')
  File "/usr/lib/python2.7/dist-packages/MySQLdb/__init__.py", line 81, in Connect
    return Connection(*args, **kwargs)
  File "/usr/lib/python2.7/dist-packages/MySQLdb/connections.py", line 187, in __init__
    super(Connection, self).__init__(*args, **kwargs2)
OperationalError: (2003, "Can't connect to MySQL server on '192.168.65.148' (111)")
Fri Jul 31 16:41:52 2015  Fri Jul 31 16:41:52 2015  Mysql Error 2003: Can't connect to MySQL server on '192.168.65.148' (111) sql: 
Traceback (most recent call last):
  File "../server_base/mysql_handle.py", line 74, in connect_MySQL
    self.mysql_db, charset='utf8')
  File "/usr/lib/python2.7/dist-packages/MySQLdb/__init__.py", line 81, in Connect
    return Connection(*args, **kwargs)
  File "/usr/lib/python2.7/dist-packages/MySQLdb/connections.py", line 187, in __init__
    super(Connection, self).__init__(*args, **kwargs2)
OperationalError: (2003, "Can't connect to MySQL server on '192.168.65.148' (111)")
Fri Jul 31 16:42:43 2015  Fri Jul 31 16:42:43 2015  Mysql Error 2003: Can't connect to MySQL server on '192.168.65.148' (111) sql: 
Traceback (most recent call last):
  File "../server_base/mysql_handle.py", line 74, in connect_MySQL
    self.mysql_db, charset='utf8')
  File "/usr/lib/python2.7/dist-packages/MySQLdb/__init__.py", line 81, in Connect
    return Connection(*args, **kwargs)
  File "/usr/lib/python2.7/dist-packages/MySQLdb/connections.py", line 187, in __init__
    super(Connection, self).__init__(*args, **kwargs2)
OperationalError: (2003, "Can't connect to MySQL server on '192.168.65.148' (111)")
Fri Jul 31 16:43:34 2015  Fri Jul 31 16:43:34 2015  Mysql Error 2003: Can't connect to MySQL server on '192.168.65.148' (111) sql: 
Traceback (most recent call last):
  File "../server_base/mysql_handle.py", line 74, in connect_MySQL
    self.mysql_db, charset='utf8')
  File "/usr/lib/python2.7/dist-packages/MySQLdb/__init__.py", line 81, in Connect
    return Connection(*args, **kwargs)
  File "/usr/lib/python2.7/dist-packages/MySQLdb/connections.py", line 187, in __init__
    super(Connection, self).__init__(*args, **kwargs2)
OperationalError: (2003, "Can't connect to MySQL server on '192.168.65.148' (111)")
Fri Jul 31 16:44:25 2015  Fri Jul 31 16:44:25 2015  Mysql Error 2003: Can't connect to MySQL server on '192.168.65.148' (111) sql: 
Traceback (most recent call last):
  File "../server_base/mysql_handle.py", line 74, in connect_MySQL
    self.mysql_db, charset='utf8')
  File "/usr/lib/python2.7/dist-packages/MySQLdb/__init__.py", line 81, in Connect
    return Connection(*args, **kwargs)
  File "/usr/lib/python2.7/dist-packages/MySQLdb/connections.py", line 187, in __init__
    super(Connection, self).__init__(*args, **kwargs2)
OperationalError: (2003, "Can't connect to MySQL server on '192.168.65.148' (111)")
Fri Jul 31 16:45:16 2015  Fri Jul 31 16:45:16 2015  Mysql Error 2003: Can't connect to MySQL server on '192.168.65.148' (111) sql: 
Traceback (most recent call last):
  File "../server_base/mysql_handle.py", line 74, in connect_MySQL
    self.mysql_db, charset='utf8')
  File "/usr/lib/python2.7/dist-packages/MySQLdb/__init__.py", line 81, in Connect
    return Connection(*args, **kwargs)
  File "/usr/lib/python2.7/dist-packages/MySQLdb/connections.py", line 187, in __init__
    super(Connection, self).__init__(*args, **kwargs2)
OperationalError: (2003, "Can't connect to MySQL server on '192.168.65.148' (111)")
Fri Jul 31 16:46:07 2015  Fri Jul 31 16:46:07 2015  Mysql Error 2003: Can't connect to MySQL server on '192.168.65.148' (111) sql: 
Traceback (most recent call last):
  File "../server_base/mysql_handle.py", line 74, in connect_MySQL
    self.mysql_db, charset='utf8')
  File "/usr/lib/python2.7/dist-packages/MySQLdb/__init__.py", line 81, in Connect
    return Connection(*args, **kwargs)
  File "/usr/lib/python2.7/dist-packages/MySQLdb/connections.py", line 187, in __init__
    super(Connection, self).__init__(*args, **kwargs2)
OperationalError: (2003, "Can't connect to MySQL server on '192.168.65.148' (111)")
Fri Jul 31 16:46:58 2015  Fri Jul 31 16:46:58 2015  Mysql Error 2003: Can't connect to MySQL server on '192.168.65.148' (111) sql: 
Traceback (most recent call last):
  File "../server_base/mysql_handle.py", line 74, in connect_MySQL
    self.mysql_db, charset='utf8')
  File "/usr/lib/python2.7/dist-packages/MySQLdb/__init__.py", line 81, in Connect
    return Connection(*args, **kwargs)
  File "/usr/lib/python2.7/dist-packages/MySQLdb/connections.py", line 187, in __init__
    super(Connection, self).__init__(*args, **kwargs2)
OperationalError: (2003, "Can't connect to MySQL server on '192.168.65.148' (111)")
Fri Jul 31 16:47:29 2015  Fri Jul 31 16:47:29 2015  Mysql Error 2003: Can't connect to MySQL server on '192.168.65.148' (113) sql: 
Traceback (most recent call last):
  File "../server_base/mysql_handle.py", line 74, in connect_MySQL
    self.mysql_db, charset='utf8')
  File "/usr/lib/python2.7/dist-packages/MySQLdb/__init__.py", line 81, in Connect
    return Connection(*args, **kwargs)
  File "/usr/lib/python2.7/dist-packages/MySQLdb/connections.py", line 187, in __init__
    super(Connection, self).__init__(*args, **kwargs2)
OperationalError: (2003, "Can't connect to MySQL server on '192.168.65.148' (113)")
Fri Jul 31 16:48:00 2015  Fri Jul 31 16:48:00 2015  Mysql Error 2003: Can't connect to MySQL server on '192.168.65.148' (113) sql: 
Traceback (most recent call last):
  File "../server_base/mysql_handle.py", line 74, in connect_MySQL
    self.mysql_db, charset='utf8')
  File "/usr/lib/python2.7/dist-packages/MySQLdb/__init__.py", line 81, in Connect
    return Connection(*args, **kwargs)
  File "/usr/lib/python2.7/dist-packages/MySQLdb/connections.py", line 187, in __init__
    super(Connection, self).__init__(*args, **kwargs2)
OperationalError: (2003, "Can't connect to MySQL server on '192.168.65.148' (113)")
Fri Jul 31 16:48:33 2015  Fri Jul 31 16:48:33 2015  Mysql Error 2003: Can't connect to MySQL server on '192.168.65.148' (113) sql: 
Traceback (most recent call last):
  File "../server_base/mysql_handle.py", line 74, in connect_MySQL
    self.mysql_db, charset='utf8')
  File "/usr/lib/python2.7/dist-packages/MySQLdb/__init__.py", line 81, in Connect
    return Connection(*args, **kwargs)
  File "/usr/lib/python2.7/dist-packages/MySQLdb/connections.py", line 187, in __init__
    super(Connection, self).__init__(*args, **kwargs2)
OperationalError: (2003, "Can't connect to MySQL server on '192.168.65.148' (113)")
Fri Jul 31 16:49:06 2015  Fri Jul 31 16:49:06 2015  Mysql Error 2003: Can't connect to MySQL server on '192.168.65.148' (113) sql: 
Traceback (most recent call last):
  File "../server_base/mysql_handle.py", line 74, in connect_MySQL
    self.mysql_db, charset='utf8')
  File "/usr/lib/python2.7/dist-packages/MySQLdb/__init__.py", line 81, in Connect
    return Connection(*args, **kwargs)
  File "/usr/lib/python2.7/dist-packages/MySQLdb/connections.py", line 187, in __init__
    super(Connection, self).__init__(*args, **kwargs2)
OperationalError: (2003, "Can't connect to MySQL server on '192.168.65.148' (113)")
Fri Jul 31 16:49:36 2015  Fri Jul 31 16:49:36 2015  Mysql Error 2003: Can't connect to MySQL server on '192.168.65.148' (113) sql: 
Traceback (most recent call last):
  File "../server_base/mysql_handle.py", line 74, in connect_MySQL
    self.mysql_db, charset='utf8')
  File "/usr/lib/python2.7/dist-packages/MySQLdb/__init__.py", line 81, in Connect
    return Connection(*args, **kwargs)
  File "/usr/lib/python2.7/dist-packages/MySQLdb/connections.py", line 187, in __init__
    super(Connection, self).__init__(*args, **kwargs2)
OperationalError: (2003, "Can't connect to MySQL server on '192.168.65.148' (113)")
Fri Jul 31 16:50:09 2015  Fri Jul 31 16:50:09 2015  Mysql Error 2003: Can't connect to MySQL server on '192.168.65.148' (113) sql: 
Traceback (most recent call last):
  File "../server_base/mysql_handle.py", line 74, in connect_MySQL
    self.mysql_db, charset='utf8')
  File "/usr/lib/python2.7/dist-packages/MySQLdb/__init__.py", line 81, in Connect
    return Connection(*args, **kwargs)
  File "/usr/lib/python2.7/dist-packages/MySQLdb/connections.py", line 187, in __init__
    super(Connection, self).__init__(*args, **kwargs2)
OperationalError: (2003, "Can't connect to MySQL server on '192.168.65.148' (113)")
Fri Jul 31 16:50:39 2015  Fri Jul 31 16:50:39 2015  Mysql Error 2003: Can't connect to MySQL server on '192.168.65.148' (101) sql: 
Traceback (most recent call last):
  File "../server_base/mysql_handle.py", line 74, in connect_MySQL
    self.mysql_db, charset='utf8')
  File "/usr/lib/python2.7/dist-packages/MySQLdb/__init__.py", line 81, in Connect
    return Connection(*args, **kwargs)
  File "/usr/lib/python2.7/dist-packages/MySQLdb/connections.py", line 187, in __init__
    super(Connection, self).__init__(*args, **kwargs2)
OperationalError: (2003, "Can't connect to MySQL server on '192.168.65.148' (101)")
Fri Jul 31 16:51:30 2015  Fri Jul 31 16:51:30 2015  Mysql Error 2003: Can't connect to MySQL server on '192.168.65.148' (111) sql: 
Traceback (most recent call last):
  File "../server_base/mysql_handle.py", line 74, in connect_MySQL
    self.mysql_db, charset='utf8')
  File "/usr/lib/python2.7/dist-packages/MySQLdb/__init__.py", line 81, in Connect
    return Connection(*args, **kwargs)
  File "/usr/lib/python2.7/dist-packages/MySQLdb/connections.py", line 187, in __init__
    super(Connection, self).__init__(*args, **kwargs2)
OperationalError: (2003, "Can't connect to MySQL server on '192.168.65.148' (111)")
Fri Jul 31 16:52:21 2015  Fri Jul 31 16:52:21 2015  Mysql Error 2003: Can't connect to MySQL server on '192.168.65.148' (111) sql: 
Traceback (most recent call last):
  File "../server_base/mysql_handle.py", line 74, in connect_MySQL
    self.mysql_db, charset='utf8')
  File "/usr/lib/python2.7/dist-packages/MySQLdb/__init__.py", line 81, in Connect
    return Connection(*args, **kwargs)
  File "/usr/lib/python2.7/dist-packages/MySQLdb/connections.py", line 187, in __init__
    super(Connection, self).__init__(*args, **kwargs2)
OperationalError: (2003, "Can't connect to MySQL server on '192.168.65.148' (111)")
Fri Jul 31 16:53:12 2015  Fri Jul 31 16:53:12 2015  Mysql Error 2003: Can't connect to MySQL server on '192.168.65.148' (111) sql: 
Traceback (most recent call last):
  File "../server_base/mysql_handle.py", line 74, in connect_MySQL
    self.mysql_db, charset='utf8')
  File "/usr/lib/python2.7/dist-packages/MySQLdb/__init__.py", line 81, in Connect
    return Connection(*args, **kwargs)
  File "/usr/lib/python2.7/dist-packages/MySQLdb/connections.py", line 187, in __init__
    super(Connection, self).__init__(*args, **kwargs2)
OperationalError: (2003, "Can't connect to MySQL server on '192.168.65.148' (111)")
Fri Jul 31 16:54:04 2015  Fri Jul 31 16:54:04 2015  Mysql Error 2003: Can't connect to MySQL server on '192.168.65.148' (111) sql: 
Traceback (most recent call last):
  File "../server_base/mysql_handle.py", line 74, in connect_MySQL
    self.mysql_db, charset='utf8')
  File "/usr/lib/python2.7/dist-packages/MySQLdb/__init__.py", line 81, in Connect
    return Connection(*args, **kwargs)
  File "/usr/lib/python2.7/dist-packages/MySQLdb/connections.py", line 187, in __init__
    super(Connection, self).__init__(*args, **kwargs2)
OperationalError: (2003, "Can't connect to MySQL server on '192.168.65.148' (111)")
Fri Jul 31 16:54:55 2015  Fri Jul 31 16:54:55 2015  Mysql Error 2003: Can't connect to MySQL server on '192.168.65.148' (111) sql: 
Traceback (most recent call last):
  File "../server_base/mysql_handle.py", line 74, in connect_MySQL
    self.mysql_db, charset='utf8')
  File "/usr/lib/python2.7/dist-packages/MySQLdb/__init__.py", line 81, in Connect
    return Connection(*args, **kwargs)
  File "/usr/lib/python2.7/dist-packages/MySQLdb/connections.py", line 187, in __init__
    super(Connection, self).__init__(*args, **kwargs2)
OperationalError: (2003, "Can't connect to MySQL server on '192.168.65.148' (111)")
Fri Jul 31 16:55:46 2015  Fri Jul 31 16:55:46 2015  Mysql Error 2003: Can't connect to MySQL server on '192.168.65.148' (111) sql: 
Traceback (most recent call last):
  File "../server_base/mysql_handle.py", line 74, in connect_MySQL
    self.mysql_db, charset='utf8')
  File "/usr/lib/python2.7/dist-packages/MySQLdb/__init__.py", line 81, in Connect
    return Connection(*args, **kwargs)
  File "/usr/lib/python2.7/dist-packages/MySQLdb/connections.py", line 187, in __init__
    super(Connection, self).__init__(*args, **kwargs2)
OperationalError: (2003, "Can't connect to MySQL server on '192.168.65.148' (111)")
Fri Jul 31 16:56:37 2015  Fri Jul 31 16:56:37 2015  Mysql Error 2003: Can't connect to MySQL server on '192.168.65.148' (111) sql: 
Traceback (most recent call last):
  File "../server_base/mysql_handle.py", line 74, in connect_MySQL
    self.mysql_db, charset='utf8')
  File "/usr/lib/python2.7/dist-packages/MySQLdb/__init__.py", line 81, in Connect
    return Connection(*args, **kwargs)
  File "/usr/lib/python2.7/dist-packages/MySQLdb/connections.py", line 187, in __init__
    super(Connection, self).__init__(*args, **kwargs2)
OperationalError: (2003, "Can't connect to MySQL server on '192.168.65.148' (111)")
Fri Jul 31 16:57:28 2015  Fri Jul 31 16:57:28 2015  Mysql Error 2003: Can't connect to MySQL server on '192.168.65.148' (111) sql: 
Traceback (most recent call last):
  File "../server_base/mysql_handle.py", line 74, in connect_MySQL
    self.mysql_db, charset='utf8')
  File "/usr/lib/python2.7/dist-packages/MySQLdb/__init__.py", line 81, in Connect
    return Connection(*args, **kwargs)
  File "/usr/lib/python2.7/dist-packages/MySQLdb/connections.py", line 187, in __init__
    super(Connection, self).__init__(*args, **kwargs2)
OperationalError: (2003, "Can't connect to MySQL server on '192.168.65.148' (111)")
Fri Jul 31 16:58:19 2015  Fri Jul 31 16:58:19 2015  Mysql Error 2003: Can't connect to MySQL server on '192.168.65.148' (111) sql: 
Traceback (most recent call last):
  File "../server_base/mysql_handle.py", line 74, in connect_MySQL
    self.mysql_db, charset='utf8')
  File "/usr/lib/python2.7/dist-packages/MySQLdb/__init__.py", line 81, in Connect
    return Connection(*args, **kwargs)
  File "/usr/lib/python2.7/dist-packages/MySQLdb/connections.py", line 187, in __init__
    super(Connection, self).__init__(*args, **kwargs2)
OperationalError: (2003, "Can't connect to MySQL server on '192.168.65.148' (111)")
Fri Jul 31 16:59:10 2015  Fri Jul 31 16:59:10 2015  Mysql Error 2003: Can't connect to MySQL server on '192.168.65.148' (111) sql: 
Traceback (most recent call last):
  File "../server_base/mysql_handle.py", line 74, in connect_MySQL
    self.mysql_db, charset='utf8')
  File "/usr/lib/python2.7/dist-packages/MySQLdb/__init__.py", line 81, in Connect
    return Connection(*args, **kwargs)
  File "/usr/lib/python2.7/dist-packages/MySQLdb/connections.py", line 187, in __init__
    super(Connection, self).__init__(*args, **kwargs2)
OperationalError: (2003, "Can't connect to MySQL server on '192.168.65.148' (111)")

***********************************************************
Fri Jul 31 17:05:10 2015: engine server start
————————————————————————————————————————————————————

***********************************************************
Fri Jul 31 17:17:50 2015: engine server start
————————————————————————————————————————————————————

***********************************************************
Fri Jul 31 19:39:37 2015: engine server start
————————————————————————————————————————————————————

***********************************************************
Fri Jul 31 20:15:46 2015: engine server start
————————————————————————————————————————————————————
Fri Jul 31 20:50:48 2015  Fri Jul 31 20:50:48 2015  Mysql Error 1317: Query execution was interrupted sql: update server_live set time='2015-07-31 20:50' where ip='192.168.174.128' and port='23464'
Traceback (most recent call last):
  File "../server_base/mysql_handle.py", line 286, in require_post
    self.cur.execute(sql)
  File "/usr/lib/python2.7/dist-packages/MySQLdb/cursors.py", line 174, in execute
    self.errorhandler(self, exc, value)
  File "/usr/lib/python2.7/dist-packages/MySQLdb/connections.py", line 36, in defaulterrorhandler
    raise errorclass, errorvalue
OperationalError: (1317, 'Query execution was interrupted')

***********************************************************
Sat Aug  1 14:58:27 2015: engine server start
————————————————————————————————————————————————————
Sat Aug  1 15:44:14 2015  Sat Aug  1 15:44:14 2015  Mysql Error 2003: Can't connect to MySQL server on '192.168.65.148' (111) sql: 
Traceback (most recent call last):
  File "../server_base/mysql_handle.py", line 74, in connect_MySQL
    self.mysql_db, charset='utf8')
  File "/usr/lib/python2.7/dist-packages/MySQLdb/__init__.py", line 81, in Connect
    return Connection(*args, **kwargs)
  File "/usr/lib/python2.7/dist-packages/MySQLdb/connections.py", line 187, in __init__
    super(Connection, self).__init__(*args, **kwargs2)
OperationalError: (2003, "Can't connect to MySQL server on '192.168.65.148' (111)")
Sat Aug  1 15:44:44 2015  Sat Aug  1 15:44:44 2015  Mysql Error 1146: Table 'phishing_check.server_live' doesn't exist sql: update server_live set time='2015-08-01 15:44' where ip='192.168.174.128' and port='23464'
Traceback (most recent call last):
  File "../server_base/mysql_handle.py", line 286, in require_post
    self.cur.execute(sql)
  File "/usr/lib/python2.7/dist-packages/MySQLdb/cursors.py", line 174, in execute
    self.errorhandler(self, exc, value)
  File "/usr/lib/python2.7/dist-packages/MySQLdb/connections.py", line 36, in defaulterrorhandler
    raise errorclass, errorvalue
ProgrammingError: (1146, "Table 'phishing_check.server_live' doesn't exist")
Sat Aug  1 15:45:14 2015  Sat Aug  1 15:45:14 2015  Mysql Error 1146: Table 'phishing_check.server_live' doesn't exist sql: update server_live set time='2015-08-01 15:45' where ip='192.168.174.128' and port='23464'
Traceback (most recent call last):
  File "../server_base/mysql_handle.py", line 286, in require_post
    self.cur.execute(sql)
  File "/usr/lib/python2.7/dist-packages/MySQLdb/cursors.py", line 174, in execute
    self.errorhandler(self, exc, value)
  File "/usr/lib/python2.7/dist-packages/MySQLdb/connections.py", line 36, in defaulterrorhandler
    raise errorclass, errorvalue
ProgrammingError: (1146, "Table 'phishing_check.server_live' doesn't exist")
Sat Aug  1 15:45:44 2015  Sat Aug  1 15:45:44 2015  Mysql Error 1146: Table 'phishing_check.server_live' doesn't exist sql: update server_live set time='2015-08-01 15:45' where ip='192.168.174.128' and port='23464'
Traceback (most recent call last):
  File "../server_base/mysql_handle.py", line 286, in require_post
    self.cur.execute(sql)
  File "/usr/lib/python2.7/dist-packages/MySQLdb/cursors.py", line 174, in execute
    self.errorhandler(self, exc, value)
  File "/usr/lib/python2.7/dist-packages/MySQLdb/connections.py", line 36, in defaulterrorhandler
    raise errorclass, errorvalue
ProgrammingError: (1146, "Table 'phishing_check.server_live' doesn't exist")
Sat Aug  1 15:46:14 2015  Sat Aug  1 15:46:14 2015  Mysql Error 1146: Table 'phishing_check.server_live' doesn't exist sql: update server_live set time='2015-08-01 15:46' where ip='192.168.174.128' and port='23464'
Traceback (most recent call last):
  File "../server_base/mysql_handle.py", line 286, in require_post
    self.cur.execute(sql)
  File "/usr/lib/python2.7/dist-packages/MySQLdb/cursors.py", line 174, in execute
    self.errorhandler(self, exc, value)
  File "/usr/lib/python2.7/dist-packages/MySQLdb/connections.py", line 36, in defaulterrorhandler
    raise errorclass, errorvalue
ProgrammingError: (1146, "Table 'phishing_check.server_live' doesn't exist")
Sat Aug  1 15:46:44 2015  Sat Aug  1 15:46:44 2015  Mysql Error 1146: Table 'phishing_check.server_live' doesn't exist sql: update server_live set time='2015-08-01 15:46' where ip='192.168.174.128' and port='23464'
Traceback (most recent call last):
  File "../server_base/mysql_handle.py", line 286, in require_post
    self.cur.execute(sql)
  File "/usr/lib/python2.7/dist-packages/MySQLdb/cursors.py", line 174, in execute
    self.errorhandler(self, exc, value)
  File "/usr/lib/python2.7/dist-packages/MySQLdb/connections.py", line 36, in defaulterrorhandler
    raise errorclass, errorvalue
ProgrammingError: (1146, "Table 'phishing_check.server_live' doesn't exist")
Sat Aug  1 15:47:14 2015  Sat Aug  1 15:47:14 2015  Mysql Error 1146: Table 'phishing_check.server_live' doesn't exist sql: update server_live set time='2015-08-01 15:47' where ip='192.168.174.128' and port='23464'
Traceback (most recent call last):
  File "../server_base/mysql_handle.py", line 286, in require_post
    self.cur.execute(sql)
  File "/usr/lib/python2.7/dist-packages/MySQLdb/cursors.py", line 174, in execute
    self.errorhandler(self, exc, value)
  File "/usr/lib/python2.7/dist-packages/MySQLdb/connections.py", line 36, in defaulterrorhandler
    raise errorclass, errorvalue
ProgrammingError: (1146, "Table 'phishing_check.server_live' doesn't exist")
Sat Aug  1 15:47:44 2015  Sat Aug  1 15:47:44 2015  Mysql Error 1146: Table 'phishing_check.server_live' doesn't exist sql: update server_live set time='2015-08-01 15:47' where ip='192.168.174.128' and port='23464'
Traceback (most recent call last):
  File "../server_base/mysql_handle.py", line 286, in require_post
    self.cur.execute(sql)
  File "/usr/lib/python2.7/dist-packages/MySQLdb/cursors.py", line 174, in execute
    self.errorhandler(self, exc, value)
  File "/usr/lib/python2.7/dist-packages/MySQLdb/connections.py", line 36, in defaulterrorhandler
    raise errorclass, errorvalue
ProgrammingError: (1146, "Table 'phishing_check.server_live' doesn't exist")
Sat Aug  1 15:48:14 2015  Sat Aug  1 15:48:14 2015  Mysql Error 1146: Table 'phishing_check.server_live' doesn't exist sql: update server_live set time='2015-08-01 15:48' where ip='192.168.174.128' and port='23464'
Traceback (most recent call last):
  File "../server_base/mysql_handle.py", line 286, in require_post
    self.cur.execute(sql)
  File "/usr/lib/python2.7/dist-packages/MySQLdb/cursors.py", line 174, in execute
    self.errorhandler(self, exc, value)
  File "/usr/lib/python2.7/dist-packages/MySQLdb/connections.py", line 36, in defaulterrorhandler
    raise errorclass, errorvalue
ProgrammingError: (1146, "Table 'phishing_check.server_live' doesn't exist")
Sat Aug  1 15:48:44 2015  Sat Aug  1 15:48:44 2015  Mysql Error 1146: Table 'phishing_check.server_live' doesn't exist sql: update server_live set time='2015-08-01 15:48' where ip='192.168.174.128' and port='23464'
Traceback (most recent call last):
  File "../server_base/mysql_handle.py", line 286, in require_post
    self.cur.execute(sql)
  File "/usr/lib/python2.7/dist-packages/MySQLdb/cursors.py", line 174, in execute
    self.errorhandler(self, exc, value)
  File "/usr/lib/python2.7/dist-packages/MySQLdb/connections.py", line 36, in defaulterrorhandler
    raise errorclass, errorvalue
ProgrammingError: (1146, "Table 'phishing_check.server_live' doesn't exist")
Sat Aug  1 15:49:14 2015  Sat Aug  1 15:49:14 2015  Mysql Error 1146: Table 'phishing_check.server_live' doesn't exist sql: update server_live set time='2015-08-01 15:49' where ip='192.168.174.128' and port='23464'
Traceback (most recent call last):
  File "../server_base/mysql_handle.py", line 286, in require_post
    self.cur.execute(sql)
  File "/usr/lib/python2.7/dist-packages/MySQLdb/cursors.py", line 174, in execute
    self.errorhandler(self, exc, value)
  File "/usr/lib/python2.7/dist-packages/MySQLdb/connections.py", line 36, in defaulterrorhandler
    raise errorclass, errorvalue
ProgrammingError: (1146, "Table 'phishing_check.server_live' doesn't exist")
Sat Aug  1 15:49:44 2015  Sat Aug  1 15:49:44 2015  Mysql Error 1146: Table 'phishing_check.server_live' doesn't exist sql: update server_live set time='2015-08-01 15:49' where ip='192.168.174.128' and port='23464'
Traceback (most recent call last):
  File "../server_base/mysql_handle.py", line 286, in require_post
    self.cur.execute(sql)
  File "/usr/lib/python2.7/dist-packages/MySQLdb/cursors.py", line 174, in execute
    self.errorhandler(self, exc, value)
  File "/usr/lib/python2.7/dist-packages/MySQLdb/connections.py", line 36, in defaulterrorhandler
    raise errorclass, errorvalue
ProgrammingError: (1146, "Table 'phishing_check.server_live' doesn't exist")
Sat Aug  1 15:50:14 2015  Sat Aug  1 15:50:14 2015  Mysql Error 1146: Table 'phishing_check.server_live' doesn't exist sql: update server_live set time='2015-08-01 15:50' where ip='192.168.174.128' and port='23464'
Traceback (most recent call last):
  File "../server_base/mysql_handle.py", line 286, in require_post
    self.cur.execute(sql)
  File "/usr/lib/python2.7/dist-packages/MySQLdb/cursors.py", line 174, in execute
    self.errorhandler(self, exc, value)
  File "/usr/lib/python2.7/dist-packages/MySQLdb/connections.py", line 36, in defaulterrorhandler
    raise errorclass, errorvalue
ProgrammingError: (1146, "Table 'phishing_check.server_live' doesn't exist")
Sat Aug  1 15:50:44 2015  Sat Aug  1 15:50:44 2015  Mysql Error 1146: Table 'phishing_check.server_live' doesn't exist sql: update server_live set time='2015-08-01 15:50' where ip='192.168.174.128' and port='23464'
Traceback (most recent call last):
  File "../server_base/mysql_handle.py", line 286, in require_post
    self.cur.execute(sql)
  File "/usr/lib/python2.7/dist-packages/MySQLdb/cursors.py", line 174, in execute
    self.errorhandler(self, exc, value)
  File "/usr/lib/python2.7/dist-packages/MySQLdb/connections.py", line 36, in defaulterrorhandler
    raise errorclass, errorvalue
ProgrammingError: (1146, "Table 'phishing_check.server_live' doesn't exist")
Sat Aug  1 15:51:15 2015  Sat Aug  1 15:51:15 2015  Mysql Error 1146: Table 'phishing_check.server_live' doesn't exist sql: update server_live set time='2015-08-01 15:51' where ip='192.168.174.128' and port='23464'
Traceback (most recent call last):
  File "../server_base/mysql_handle.py", line 286, in require_post
    self.cur.execute(sql)
  File "/usr/lib/python2.7/dist-packages/MySQLdb/cursors.py", line 174, in execute
    self.errorhandler(self, exc, value)
  File "/usr/lib/python2.7/dist-packages/MySQLdb/connections.py", line 36, in defaulterrorhandler
    raise errorclass, errorvalue
ProgrammingError: (1146, "Table 'phishing_check.server_live' doesn't exist")
Sat Aug  1 15:51:45 2015  Sat Aug  1 15:51:45 2015  Mysql Error 1146: Table 'phishing_check.server_live' doesn't exist sql: update server_live set time='2015-08-01 15:51' where ip='192.168.174.128' and port='23464'
Traceback (most recent call last):
  File "../server_base/mysql_handle.py", line 286, in require_post
    self.cur.execute(sql)
  File "/usr/lib/python2.7/dist-packages/MySQLdb/cursors.py", line 174, in execute
    self.errorhandler(self, exc, value)
  File "/usr/lib/python2.7/dist-packages/MySQLdb/connections.py", line 36, in defaulterrorhandler
    raise errorclass, errorvalue
ProgrammingError: (1146, "Table 'phishing_check.server_live' doesn't exist")

***********************************************************
Sat Aug  1 16:12:35 2015: engine server start
————————————————————————————————————————————————————

***********************************************************
Sat Aug  1 17:46:43 2015: engine server start
————————————————————————————————————————————————————
Sat Aug  1 20:50:24 2015  Sat Aug  1 20:50:24 2015  Mysql Error 1317: Query execution was interrupted sql: update server_live set time='2015-08-01 20:50' where ip='192.168.174.128' and port='23464'
Traceback (most recent call last):
  File "../server_base/mysql_handle.py", line 286, in require_post
    self.cur.execute(sql)
  File "/usr/lib/python2.7/dist-packages/MySQLdb/cursors.py", line 174, in execute
    self.errorhandler(self, exc, value)
  File "/usr/lib/python2.7/dist-packages/MySQLdb/connections.py", line 36, in defaulterrorhandler
    raise errorclass, errorvalue
OperationalError: (1317, 'Query execution was interrupted')

***********************************************************
Sun Aug  2 11:51:33 2015: engine server start
————————————————————————————————————————————————————
Sun Aug  2 14:52:57 2015  Sun Aug  2 14:52:57 2015  Mysql Error 2003: Can't connect to MySQL server on '192.168.65.148' (111) sql: 
Traceback (most recent call last):
  File "../server_base/mysql_handle.py", line 74, in connect_MySQL
    self.mysql_db, charset='utf8')
  File "/usr/lib/python2.7/dist-packages/MySQLdb/__init__.py", line 81, in Connect
    return Connection(*args, **kwargs)
  File "/usr/lib/python2.7/dist-packages/MySQLdb/connections.py", line 187, in __init__
    super(Connection, self).__init__(*args, **kwargs2)
OperationalError: (2003, "Can't connect to MySQL server on '192.168.65.148' (111)")
Sun Aug  2 14:53:27 2015  Sun Aug  2 14:53:27 2015  Mysql Error 2003: Can't connect to MySQL server on '192.168.65.148' (101) sql: 
Traceback (most recent call last):
  File "../server_base/mysql_handle.py", line 74, in connect_MySQL
    self.mysql_db, charset='utf8')
  File "/usr/lib/python2.7/dist-packages/MySQLdb/__init__.py", line 81, in Connect
    return Connection(*args, **kwargs)
  File "/usr/lib/python2.7/dist-packages/MySQLdb/connections.py", line 187, in __init__
    super(Connection, self).__init__(*args, **kwargs2)
OperationalError: (2003, "Can't connect to MySQL server on '192.168.65.148' (101)")
Sun Aug  2 14:54:00 2015  Sun Aug  2 14:54:00 2015  Mysql Error 2003: Can't connect to MySQL server on '192.168.65.148' (113) sql: 
Traceback (most recent call last):
  File "../server_base/mysql_handle.py", line 74, in connect_MySQL
    self.mysql_db, charset='utf8')
  File "/usr/lib/python2.7/dist-packages/MySQLdb/__init__.py", line 81, in Connect
    return Connection(*args, **kwargs)
  File "/usr/lib/python2.7/dist-packages/MySQLdb/connections.py", line 187, in __init__
    super(Connection, self).__init__(*args, **kwargs2)
OperationalError: (2003, "Can't connect to MySQL server on '192.168.65.148' (113)")
Sun Aug  2 14:54:33 2015  Sun Aug  2 14:54:33 2015  Mysql Error 2003: Can't connect to MySQL server on '192.168.65.148' (113) sql: 
Traceback (most recent call last):
  File "../server_base/mysql_handle.py", line 74, in connect_MySQL
    self.mysql_db, charset='utf8')
  File "/usr/lib/python2.7/dist-packages/MySQLdb/__init__.py", line 81, in Connect
    return Connection(*args, **kwargs)
  File "/usr/lib/python2.7/dist-packages/MySQLdb/connections.py", line 187, in __init__
    super(Connection, self).__init__(*args, **kwargs2)
OperationalError: (2003, "Can't connect to MySQL server on '192.168.65.148' (113)")
Sun Aug  2 14:55:06 2015  Sun Aug  2 14:55:06 2015  Mysql Error 2003: Can't connect to MySQL server on '192.168.65.148' (113) sql: 
Traceback (most recent call last):
  File "../server_base/mysql_handle.py", line 74, in connect_MySQL
    self.mysql_db, charset='utf8')
  File "/usr/lib/python2.7/dist-packages/MySQLdb/__init__.py", line 81, in Connect
    return Connection(*args, **kwargs)
  File "/usr/lib/python2.7/dist-packages/MySQLdb/connections.py", line 187, in __init__
    super(Connection, self).__init__(*args, **kwargs2)
OperationalError: (2003, "Can't connect to MySQL server on '192.168.65.148' (113)")
Sun Aug  2 14:55:39 2015  Sun Aug  2 14:55:39 2015  Mysql Error 2003: Can't connect to MySQL server on '192.168.65.148' (113) sql: 
Traceback (most recent call last):
  File "../server_base/mysql_handle.py", line 74, in connect_MySQL
    self.mysql_db, charset='utf8')
  File "/usr/lib/python2.7/dist-packages/MySQLdb/__init__.py", line 81, in Connect
    return Connection(*args, **kwargs)
  File "/usr/lib/python2.7/dist-packages/MySQLdb/connections.py", line 187, in __init__
    super(Connection, self).__init__(*args, **kwargs2)
OperationalError: (2003, "Can't connect to MySQL server on '192.168.65.148' (113)")
Sun Aug  2 14:56:12 2015  Sun Aug  2 14:56:12 2015  Mysql Error 2003: Can't connect to MySQL server on '192.168.65.148' (113) sql: 
Traceback (most recent call last):
  File "../server_base/mysql_handle.py", line 74, in connect_MySQL
    self.mysql_db, charset='utf8')
  File "/usr/lib/python2.7/dist-packages/MySQLdb/__init__.py", line 81, in Connect
    return Connection(*args, **kwargs)
  File "/usr/lib/python2.7/dist-packages/MySQLdb/connections.py", line 187, in __init__
    super(Connection, self).__init__(*args, **kwargs2)
OperationalError: (2003, "Can't connect to MySQL server on '192.168.65.148' (113)")
Sun Aug  2 14:56:45 2015  Sun Aug  2 14:56:45 2015  Mysql Error 2003: Can't connect to MySQL server on '192.168.65.148' (113) sql: 
Traceback (most recent call last):
  File "../server_base/mysql_handle.py", line 74, in connect_MySQL
    self.mysql_db, charset='utf8')
  File "/usr/lib/python2.7/dist-packages/MySQLdb/__init__.py", line 81, in Connect
    return Connection(*args, **kwargs)
  File "/usr/lib/python2.7/dist-packages/MySQLdb/connections.py", line 187, in __init__
    super(Connection, self).__init__(*args, **kwargs2)
OperationalError: (2003, "Can't connect to MySQL server on '192.168.65.148' (113)")
Sun Aug  2 14:57:18 2015  Sun Aug  2 14:57:18 2015  Mysql Error 2003: Can't connect to MySQL server on '192.168.65.148' (113) sql: 
Traceback (most recent call last):
  File "../server_base/mysql_handle.py", line 74, in connect_MySQL
    self.mysql_db, charset='utf8')
  File "/usr/lib/python2.7/dist-packages/MySQLdb/__init__.py", line 81, in Connect
    return Connection(*args, **kwargs)
  File "/usr/lib/python2.7/dist-packages/MySQLdb/connections.py", line 187, in __init__
    super(Connection, self).__init__(*args, **kwargs2)
OperationalError: (2003, "Can't connect to MySQL server on '192.168.65.148' (113)")
Sun Aug  2 14:57:51 2015  Sun Aug  2 14:57:51 2015  Mysql Error 2003: Can't connect to MySQL server on '192.168.65.148' (113) sql: 
Traceback (most recent call last):
  File "../server_base/mysql_handle.py", line 74, in connect_MySQL
    self.mysql_db, charset='utf8')
  File "/usr/lib/python2.7/dist-packages/MySQLdb/__init__.py", line 81, in Connect
    return Connection(*args, **kwargs)
  File "/usr/lib/python2.7/dist-packages/MySQLdb/connections.py", line 187, in __init__
    super(Connection, self).__init__(*args, **kwargs2)
OperationalError: (2003, "Can't connect to MySQL server on '192.168.65.148' (113)")
Sun Aug  2 14:58:24 2015  Sun Aug  2 14:58:24 2015  Mysql Error 2003: Can't connect to MySQL server on '192.168.65.148' (113) sql: 
Traceback (most recent call last):
  File "../server_base/mysql_handle.py", line 74, in connect_MySQL
    self.mysql_db, charset='utf8')
  File "/usr/lib/python2.7/dist-packages/MySQLdb/__init__.py", line 81, in Connect
    return Connection(*args, **kwargs)
  File "/usr/lib/python2.7/dist-packages/MySQLdb/connections.py", line 187, in __init__
    super(Connection, self).__init__(*args, **kwargs2)
OperationalError: (2003, "Can't connect to MySQL server on '192.168.65.148' (113)")
Sun Aug  2 14:58:57 2015  Sun Aug  2 14:58:57 2015  Mysql Error 2003: Can't connect to MySQL server on '192.168.65.148' (113) sql: 
Traceback (most recent call last):
  File "../server_base/mysql_handle.py", line 74, in connect_MySQL
    self.mysql_db, charset='utf8')
  File "/usr/lib/python2.7/dist-packages/MySQLdb/__init__.py", line 81, in Connect
    return Connection(*args, **kwargs)
  File "/usr/lib/python2.7/dist-packages/MySQLdb/connections.py", line 187, in __init__
    super(Connection, self).__init__(*args, **kwargs2)
OperationalError: (2003, "Can't connect to MySQL server on '192.168.65.148' (113)")
Sun Aug  2 14:59:30 2015  Sun Aug  2 14:59:30 2015  Mysql Error 2003: Can't connect to MySQL server on '192.168.65.148' (113) sql: 
Traceback (most recent call last):
  File "../server_base/mysql_handle.py", line 74, in connect_MySQL
    self.mysql_db, charset='utf8')
  File "/usr/lib/python2.7/dist-packages/MySQLdb/__init__.py", line 81, in Connect
    return Connection(*args, **kwargs)
  File "/usr/lib/python2.7/dist-packages/MySQLdb/connections.py", line 187, in __init__
    super(Connection, self).__init__(*args, **kwargs2)
OperationalError: (2003, "Can't connect to MySQL server on '192.168.65.148' (113)")
Sun Aug  2 15:00:03 2015  Sun Aug  2 15:00:03 2015  Mysql Error 2003: Can't connect to MySQL server on '192.168.65.148' (113) sql: 
Traceback (most recent call last):
  File "../server_base/mysql_handle.py", line 74, in connect_MySQL
    self.mysql_db, charset='utf8')
  File "/usr/lib/python2.7/dist-packages/MySQLdb/__init__.py", line 81, in Connect
    return Connection(*args, **kwargs)
  File "/usr/lib/python2.7/dist-packages/MySQLdb/connections.py", line 187, in __init__
    super(Connection, self).__init__(*args, **kwargs2)
OperationalError: (2003, "Can't connect to MySQL server on '192.168.65.148' (113)")
Sun Aug  2 15:00:36 2015  Sun Aug  2 15:00:36 2015  Mysql Error 2003: Can't connect to MySQL server on '192.168.65.148' (113) sql: 
Traceback (most recent call last):
  File "../server_base/mysql_handle.py", line 74, in connect_MySQL
    self.mysql_db, charset='utf8')
  File "/usr/lib/python2.7/dist-packages/MySQLdb/__init__.py", line 81, in Connect
    return Connection(*args, **kwargs)
  File "/usr/lib/python2.7/dist-packages/MySQLdb/connections.py", line 187, in __init__
    super(Connection, self).__init__(*args, **kwargs2)
OperationalError: (2003, "Can't connect to MySQL server on '192.168.65.148' (113)")
Sun Aug  2 15:01:09 2015  Sun Aug  2 15:01:09 2015  Mysql Error 2003: Can't connect to MySQL server on '192.168.65.148' (113) sql: 
Traceback (most recent call last):
  File "../server_base/mysql_handle.py", line 74, in connect_MySQL
    self.mysql_db, charset='utf8')
  File "/usr/lib/python2.7/dist-packages/MySQLdb/__init__.py", line 81, in Connect
    return Connection(*args, **kwargs)
  File "/usr/lib/python2.7/dist-packages/MySQLdb/connections.py", line 187, in __init__
    super(Connection, self).__init__(*args, **kwargs2)
OperationalError: (2003, "Can't connect to MySQL server on '192.168.65.148' (113)")
Sun Aug  2 15:01:42 2015  Sun Aug  2 15:01:42 2015  Mysql Error 2003: Can't connect to MySQL server on '192.168.65.148' (113) sql: 
Traceback (most recent call last):
  File "../server_base/mysql_handle.py", line 74, in connect_MySQL
    self.mysql_db, charset='utf8')
  File "/usr/lib/python2.7/dist-packages/MySQLdb/__init__.py", line 81, in Connect
    return Connection(*args, **kwargs)
  File "/usr/lib/python2.7/dist-packages/MySQLdb/connections.py", line 187, in __init__
    super(Connection, self).__init__(*args, **kwargs2)
OperationalError: (2003, "Can't connect to MySQL server on '192.168.65.148' (113)")
Sun Aug  2 15:02:15 2015  Sun Aug  2 15:02:15 2015  Mysql Error 2003: Can't connect to MySQL server on '192.168.65.148' (113) sql: 
Traceback (most recent call last):
  File "../server_base/mysql_handle.py", line 74, in connect_MySQL
    self.mysql_db, charset='utf8')
  File "/usr/lib/python2.7/dist-packages/MySQLdb/__init__.py", line 81, in Connect
    return Connection(*args, **kwargs)
  File "/usr/lib/python2.7/dist-packages/MySQLdb/connections.py", line 187, in __init__
    super(Connection, self).__init__(*args, **kwargs2)
OperationalError: (2003, "Can't connect to MySQL server on '192.168.65.148' (113)")
Sun Aug  2 15:02:48 2015  Sun Aug  2 15:02:48 2015  Mysql Error 2003: Can't connect to MySQL server on '192.168.65.148' (113) sql: 
Traceback (most recent call last):
  File "../server_base/mysql_handle.py", line 74, in connect_MySQL
    self.mysql_db, charset='utf8')
  File "/usr/lib/python2.7/dist-packages/MySQLdb/__init__.py", line 81, in Connect
    return Connection(*args, **kwargs)
  File "/usr/lib/python2.7/dist-packages/MySQLdb/connections.py", line 187, in __init__
    super(Connection, self).__init__(*args, **kwargs2)
OperationalError: (2003, "Can't connect to MySQL server on '192.168.65.148' (113)")
Sun Aug  2 15:03:21 2015  Sun Aug  2 15:03:21 2015  Mysql Error 2003: Can't connect to MySQL server on '192.168.65.148' (113) sql: 
Traceback (most recent call last):
  File "../server_base/mysql_handle.py", line 74, in connect_MySQL
    self.mysql_db, charset='utf8')
  File "/usr/lib/python2.7/dist-packages/MySQLdb/__init__.py", line 81, in Connect
    return Connection(*args, **kwargs)
  File "/usr/lib/python2.7/dist-packages/MySQLdb/connections.py", line 187, in __init__
    super(Connection, self).__init__(*args, **kwargs2)
OperationalError: (2003, "Can't connect to MySQL server on '192.168.65.148' (113)")
Sun Aug  2 15:03:54 2015  Sun Aug  2 15:03:54 2015  Mysql Error 2003: Can't connect to MySQL server on '192.168.65.148' (113) sql: 
Traceback (most recent call last):
  File "../server_base/mysql_handle.py", line 74, in connect_MySQL
    self.mysql_db, charset='utf8')
  File "/usr/lib/python2.7/dist-packages/MySQLdb/__init__.py", line 81, in Connect
    return Connection(*args, **kwargs)
  File "/usr/lib/python2.7/dist-packages/MySQLdb/connections.py", line 187, in __init__
    super(Connection, self).__init__(*args, **kwargs2)
OperationalError: (2003, "Can't connect to MySQL server on '192.168.65.148' (113)")
Sun Aug  2 15:04:27 2015  Sun Aug  2 15:04:27 2015  Mysql Error 2003: Can't connect to MySQL server on '192.168.65.148' (113) sql: 
Traceback (most recent call last):
  File "../server_base/mysql_handle.py", line 74, in connect_MySQL
    self.mysql_db, charset='utf8')
  File "/usr/lib/python2.7/dist-packages/MySQLdb/__init__.py", line 81, in Connect
    return Connection(*args, **kwargs)
  File "/usr/lib/python2.7/dist-packages/MySQLdb/connections.py", line 187, in __init__
    super(Connection, self).__init__(*args, **kwargs2)
OperationalError: (2003, "Can't connect to MySQL server on '192.168.65.148' (113)")
Sun Aug  2 15:05:00 2015  Sun Aug  2 15:05:00 2015  Mysql Error 2003: Can't connect to MySQL server on '192.168.65.148' (113) sql: 
Traceback (most recent call last):
  File "../server_base/mysql_handle.py", line 74, in connect_MySQL
    self.mysql_db, charset='utf8')
  File "/usr/lib/python2.7/dist-packages/MySQLdb/__init__.py", line 81, in Connect
    return Connection(*args, **kwargs)
  File "/usr/lib/python2.7/dist-packages/MySQLdb/connections.py", line 187, in __init__
    super(Connection, self).__init__(*args, **kwargs2)
OperationalError: (2003, "Can't connect to MySQL server on '192.168.65.148' (113)")
Sun Aug  2 15:05:33 2015  Sun Aug  2 15:05:33 2015  Mysql Error 2003: Can't connect to MySQL server on '192.168.65.148' (113) sql: 
Traceback (most recent call last):
  File "../server_base/mysql_handle.py", line 74, in connect_MySQL
    self.mysql_db, charset='utf8')
  File "/usr/lib/python2.7/dist-packages/MySQLdb/__init__.py", line 81, in Connect
    return Connection(*args, **kwargs)
  File "/usr/lib/python2.7/dist-packages/MySQLdb/connections.py", line 187, in __init__
    super(Connection, self).__init__(*args, **kwargs2)
OperationalError: (2003, "Can't connect to MySQL server on '192.168.65.148' (113)")
Sun Aug  2 15:06:06 2015  Sun Aug  2 15:06:06 2015  Mysql Error 2003: Can't connect to MySQL server on '192.168.65.148' (113) sql: 
Traceback (most recent call last):
  File "../server_base/mysql_handle.py", line 74, in connect_MySQL
    self.mysql_db, charset='utf8')
  File "/usr/lib/python2.7/dist-packages/MySQLdb/__init__.py", line 81, in Connect
    return Connection(*args, **kwargs)
  File "/usr/lib/python2.7/dist-packages/MySQLdb/connections.py", line 187, in __init__
    super(Connection, self).__init__(*args, **kwargs2)
OperationalError: (2003, "Can't connect to MySQL server on '192.168.65.148' (113)")
Sun Aug  2 15:06:40 2015  Sun Aug  2 15:06:40 2015  Mysql Error 2003: Can't connect to MySQL server on '192.168.65.148' (113) sql: 
Traceback (most recent call last):
  File "../server_base/mysql_handle.py", line 74, in connect_MySQL
    self.mysql_db, charset='utf8')
  File "/usr/lib/python2.7/dist-packages/MySQLdb/__init__.py", line 81, in Connect
    return Connection(*args, **kwargs)
  File "/usr/lib/python2.7/dist-packages/MySQLdb/connections.py", line 187, in __init__
    super(Connection, self).__init__(*args, **kwargs2)
OperationalError: (2003, "Can't connect to MySQL server on '192.168.65.148' (113)")
Sun Aug  2 15:07:13 2015  Sun Aug  2 15:07:13 2015  Mysql Error 2003: Can't connect to MySQL server on '192.168.65.148' (113) sql: 
Traceback (most recent call last):
  File "../server_base/mysql_handle.py", line 74, in connect_MySQL
    self.mysql_db, charset='utf8')
  File "/usr/lib/python2.7/dist-packages/MySQLdb/__init__.py", line 81, in Connect
    return Connection(*args, **kwargs)
  File "/usr/lib/python2.7/dist-packages/MySQLdb/connections.py", line 187, in __init__
    super(Connection, self).__init__(*args, **kwargs2)
OperationalError: (2003, "Can't connect to MySQL server on '192.168.65.148' (113)")
Sun Aug  2 15:07:46 2015  Sun Aug  2 15:07:46 2015  Mysql Error 2003: Can't connect to MySQL server on '192.168.65.148' (113) sql: 
Traceback (most recent call last):
  File "../server_base/mysql_handle.py", line 74, in connect_MySQL
    self.mysql_db, charset='utf8')
  File "/usr/lib/python2.7/dist-packages/MySQLdb/__init__.py", line 81, in Connect
    return Connection(*args, **kwargs)
  File "/usr/lib/python2.7/dist-packages/MySQLdb/connections.py", line 187, in __init__
    super(Connection, self).__init__(*args, **kwargs2)
OperationalError: (2003, "Can't connect to MySQL server on '192.168.65.148' (113)")
Sun Aug  2 15:08:19 2015  Sun Aug  2 15:08:19 2015  Mysql Error 2003: Can't connect to MySQL server on '192.168.65.148' (113) sql: 
Traceback (most recent call last):
  File "../server_base/mysql_handle.py", line 74, in connect_MySQL
    self.mysql_db, charset='utf8')
  File "/usr/lib/python2.7/dist-packages/MySQLdb/__init__.py", line 81, in Connect
    return Connection(*args, **kwargs)
  File "/usr/lib/python2.7/dist-packages/MySQLdb/connections.py", line 187, in __init__
    super(Connection, self).__init__(*args, **kwargs2)
OperationalError: (2003, "Can't connect to MySQL server on '192.168.65.148' (113)")
Sun Aug  2 15:08:52 2015  Sun Aug  2 15:08:52 2015  Mysql Error 2003: Can't connect to MySQL server on '192.168.65.148' (113) sql: 
Traceback (most recent call last):
  File "../server_base/mysql_handle.py", line 74, in connect_MySQL
    self.mysql_db, charset='utf8')
  File "/usr/lib/python2.7/dist-packages/MySQLdb/__init__.py", line 81, in Connect
    return Connection(*args, **kwargs)
  File "/usr/lib/python2.7/dist-packages/MySQLdb/connections.py", line 187, in __init__
    super(Connection, self).__init__(*args, **kwargs2)
OperationalError: (2003, "Can't connect to MySQL server on '192.168.65.148' (113)")
Sun Aug  2 15:09:25 2015  Sun Aug  2 15:09:25 2015  Mysql Error 2003: Can't connect to MySQL server on '192.168.65.148' (113) sql: 
Traceback (most recent call last):
  File "../server_base/mysql_handle.py", line 74, in connect_MySQL
    self.mysql_db, charset='utf8')
  File "/usr/lib/python2.7/dist-packages/MySQLdb/__init__.py", line 81, in Connect
    return Connection(*args, **kwargs)
  File "/usr/lib/python2.7/dist-packages/MySQLdb/connections.py", line 187, in __init__
    super(Connection, self).__init__(*args, **kwargs2)
OperationalError: (2003, "Can't connect to MySQL server on '192.168.65.148' (113)")
Sun Aug  2 15:09:58 2015  Sun Aug  2 15:09:58 2015  Mysql Error 2003: Can't connect to MySQL server on '192.168.65.148' (113) sql: 
Traceback (most recent call last):
  File "../server_base/mysql_handle.py", line 74, in connect_MySQL
    self.mysql_db, charset='utf8')
  File "/usr/lib/python2.7/dist-packages/MySQLdb/__init__.py", line 81, in Connect
    return Connection(*args, **kwargs)
  File "/usr/lib/python2.7/dist-packages/MySQLdb/connections.py", line 187, in __init__
    super(Connection, self).__init__(*args, **kwargs2)
OperationalError: (2003, "Can't connect to MySQL server on '192.168.65.148' (113)")
Sun Aug  2 15:10:31 2015  Sun Aug  2 15:10:31 2015  Mysql Error 2003: Can't connect to MySQL server on '192.168.65.148' (113) sql: 
Traceback (most recent call last):
  File "../server_base/mysql_handle.py", line 74, in connect_MySQL
    self.mysql_db, charset='utf8')
  File "/usr/lib/python2.7/dist-packages/MySQLdb/__init__.py", line 81, in Connect
    return Connection(*args, **kwargs)
  File "/usr/lib/python2.7/dist-packages/MySQLdb/connections.py", line 187, in __init__
    super(Connection, self).__init__(*args, **kwargs2)
OperationalError: (2003, "Can't connect to MySQL server on '192.168.65.148' (113)")
Sun Aug  2 15:11:04 2015  Sun Aug  2 15:11:04 2015  Mysql Error 2003: Can't connect to MySQL server on '192.168.65.148' (113) sql: 
Traceback (most recent call last):
  File "../server_base/mysql_handle.py", line 74, in connect_MySQL
    self.mysql_db, charset='utf8')
  File "/usr/lib/python2.7/dist-packages/MySQLdb/__init__.py", line 81, in Connect
    return Connection(*args, **kwargs)
  File "/usr/lib/python2.7/dist-packages/MySQLdb/connections.py", line 187, in __init__
    super(Connection, self).__init__(*args, **kwargs2)
OperationalError: (2003, "Can't connect to MySQL server on '192.168.65.148' (113)")
Sun Aug  2 15:11:37 2015  Sun Aug  2 15:11:37 2015  Mysql Error 2003: Can't connect to MySQL server on '192.168.65.148' (113) sql: 
Traceback (most recent call last):
  File "../server_base/mysql_handle.py", line 74, in connect_MySQL
    self.mysql_db, charset='utf8')
  File "/usr/lib/python2.7/dist-packages/MySQLdb/__init__.py", line 81, in Connect
    return Connection(*args, **kwargs)
  File "/usr/lib/python2.7/dist-packages/MySQLdb/connections.py", line 187, in __init__
    super(Connection, self).__init__(*args, **kwargs2)
OperationalError: (2003, "Can't connect to MySQL server on '192.168.65.148' (113)")
Sun Aug  2 15:12:10 2015  Sun Aug  2 15:12:10 2015  Mysql Error 2003: Can't connect to MySQL server on '192.168.65.148' (113) sql: 
Traceback (most recent call last):
  File "../server_base/mysql_handle.py", line 74, in connect_MySQL
    self.mysql_db, charset='utf8')
  File "/usr/lib/python2.7/dist-packages/MySQLdb/__init__.py", line 81, in Connect
    return Connection(*args, **kwargs)
  File "/usr/lib/python2.7/dist-packages/MySQLdb/connections.py", line 187, in __init__
    super(Connection, self).__init__(*args, **kwargs2)
OperationalError: (2003, "Can't connect to MySQL server on '192.168.65.148' (113)")
Sun Aug  2 15:12:43 2015  Sun Aug  2 15:12:43 2015  Mysql Error 2003: Can't connect to MySQL server on '192.168.65.148' (113) sql: 
Traceback (most recent call last):
  File "../server_base/mysql_handle.py", line 74, in connect_MySQL
    self.mysql_db, charset='utf8')
  File "/usr/lib/python2.7/dist-packages/MySQLdb/__init__.py", line 81, in Connect
    return Connection(*args, **kwargs)
  File "/usr/lib/python2.7/dist-packages/MySQLdb/connections.py", line 187, in __init__
    super(Connection, self).__init__(*args, **kwargs2)
OperationalError: (2003, "Can't connect to MySQL server on '192.168.65.148' (113)")
Sun Aug  2 15:13:16 2015  Sun Aug  2 15:13:16 2015  Mysql Error 2003: Can't connect to MySQL server on '192.168.65.148' (113) sql: 
Traceback (most recent call last):
  File "../server_base/mysql_handle.py", line 74, in connect_MySQL
    self.mysql_db, charset='utf8')
  File "/usr/lib/python2.7/dist-packages/MySQLdb/__init__.py", line 81, in Connect
    return Connection(*args, **kwargs)
  File "/usr/lib/python2.7/dist-packages/MySQLdb/connections.py", line 187, in __init__
    super(Connection, self).__init__(*args, **kwargs2)
OperationalError: (2003, "Can't connect to MySQL server on '192.168.65.148' (113)")
Sun Aug  2 15:13:49 2015  Sun Aug  2 15:13:49 2015  Mysql Error 2003: Can't connect to MySQL server on '192.168.65.148' (113) sql: 
Traceback (most recent call last):
  File "../server_base/mysql_handle.py", line 74, in connect_MySQL
    self.mysql_db, charset='utf8')
  File "/usr/lib/python2.7/dist-packages/MySQLdb/__init__.py", line 81, in Connect
    return Connection(*args, **kwargs)
  File "/usr/lib/python2.7/dist-packages/MySQLdb/connections.py", line 187, in __init__
    super(Connection, self).__init__(*args, **kwargs2)
OperationalError: (2003, "Can't connect to MySQL server on '192.168.65.148' (113)")
Sun Aug  2 15:14:22 2015  Sun Aug  2 15:14:22 2015  Mysql Error 2003: Can't connect to MySQL server on '192.168.65.148' (113) sql: 
Traceback (most recent call last):
  File "../server_base/mysql_handle.py", line 74, in connect_MySQL
    self.mysql_db, charset='utf8')
  File "/usr/lib/python2.7/dist-packages/MySQLdb/__init__.py", line 81, in Connect
    return Connection(*args, **kwargs)
  File "/usr/lib/python2.7/dist-packages/MySQLdb/connections.py", line 187, in __init__
    super(Connection, self).__init__(*args, **kwargs2)
OperationalError: (2003, "Can't connect to MySQL server on '192.168.65.148' (113)")
Sun Aug  2 15:14:55 2015  Sun Aug  2 15:14:55 2015  Mysql Error 2003: Can't connect to MySQL server on '192.168.65.148' (113) sql: 
Traceback (most recent call last):
  File "../server_base/mysql_handle.py", line 74, in connect_MySQL
    self.mysql_db, charset='utf8')
  File "/usr/lib/python2.7/dist-packages/MySQLdb/__init__.py", line 81, in Connect
    return Connection(*args, **kwargs)
  File "/usr/lib/python2.7/dist-packages/MySQLdb/connections.py", line 187, in __init__
    super(Connection, self).__init__(*args, **kwargs2)
OperationalError: (2003, "Can't connect to MySQL server on '192.168.65.148' (113)")
Sun Aug  2 15:15:28 2015  Sun Aug  2 15:15:28 2015  Mysql Error 2003: Can't connect to MySQL server on '192.168.65.148' (113) sql: 
Traceback (most recent call last):
  File "../server_base/mysql_handle.py", line 74, in connect_MySQL
    self.mysql_db, charset='utf8')
  File "/usr/lib/python2.7/dist-packages/MySQLdb/__init__.py", line 81, in Connect
    return Connection(*args, **kwargs)
  File "/usr/lib/python2.7/dist-packages/MySQLdb/connections.py", line 187, in __init__
    super(Connection, self).__init__(*args, **kwargs2)
OperationalError: (2003, "Can't connect to MySQL server on '192.168.65.148' (113)")
Sun Aug  2 15:16:01 2015  Sun Aug  2 15:16:01 2015  Mysql Error 2003: Can't connect to MySQL server on '192.168.65.148' (113) sql: 
Traceback (most recent call last):
  File "../server_base/mysql_handle.py", line 74, in connect_MySQL
    self.mysql_db, charset='utf8')
  File "/usr/lib/python2.7/dist-packages/MySQLdb/__init__.py", line 81, in Connect
    return Connection(*args, **kwargs)
  File "/usr/lib/python2.7/dist-packages/MySQLdb/connections.py", line 187, in __init__
    super(Connection, self).__init__(*args, **kwargs2)
OperationalError: (2003, "Can't connect to MySQL server on '192.168.65.148' (113)")
Sun Aug  2 15:16:34 2015  Sun Aug  2 15:16:34 2015  Mysql Error 2003: Can't connect to MySQL server on '192.168.65.148' (113) sql: 
Traceback (most recent call last):
  File "../server_base/mysql_handle.py", line 74, in connect_MySQL
    self.mysql_db, charset='utf8')
  File "/usr/lib/python2.7/dist-packages/MySQLdb/__init__.py", line 81, in Connect
    return Connection(*args, **kwargs)
  File "/usr/lib/python2.7/dist-packages/MySQLdb/connections.py", line 187, in __init__
    super(Connection, self).__init__(*args, **kwargs2)
OperationalError: (2003, "Can't connect to MySQL server on '192.168.65.148' (113)")
Sun Aug  2 15:17:07 2015  Sun Aug  2 15:17:07 2015  Mysql Error 2003: Can't connect to MySQL server on '192.168.65.148' (113) sql: 
Traceback (most recent call last):
  File "../server_base/mysql_handle.py", line 74, in connect_MySQL
    self.mysql_db, charset='utf8')
  File "/usr/lib/python2.7/dist-packages/MySQLdb/__init__.py", line 81, in Connect
    return Connection(*args, **kwargs)
  File "/usr/lib/python2.7/dist-packages/MySQLdb/connections.py", line 187, in __init__
    super(Connection, self).__init__(*args, **kwargs2)
OperationalError: (2003, "Can't connect to MySQL server on '192.168.65.148' (113)")
Sun Aug  2 15:17:40 2015  Sun Aug  2 15:17:40 2015  Mysql Error 2003: Can't connect to MySQL server on '192.168.65.148' (113) sql: 
Traceback (most recent call last):
  File "../server_base/mysql_handle.py", line 74, in connect_MySQL
    self.mysql_db, charset='utf8')
  File "/usr/lib/python2.7/dist-packages/MySQLdb/__init__.py", line 81, in Connect
    return Connection(*args, **kwargs)
  File "/usr/lib/python2.7/dist-packages/MySQLdb/connections.py", line 187, in __init__
    super(Connection, self).__init__(*args, **kwargs2)
OperationalError: (2003, "Can't connect to MySQL server on '192.168.65.148' (113)")
Sun Aug  2 15:18:13 2015  Sun Aug  2 15:18:13 2015  Mysql Error 2003: Can't connect to MySQL server on '192.168.65.148' (113) sql: 
Traceback (most recent call last):
  File "../server_base/mysql_handle.py", line 74, in connect_MySQL
    self.mysql_db, charset='utf8')
  File "/usr/lib/python2.7/dist-packages/MySQLdb/__init__.py", line 81, in Connect
    return Connection(*args, **kwargs)
  File "/usr/lib/python2.7/dist-packages/MySQLdb/connections.py", line 187, in __init__
    super(Connection, self).__init__(*args, **kwargs2)
OperationalError: (2003, "Can't connect to MySQL server on '192.168.65.148' (113)")
Sun Aug  2 15:18:46 2015  Sun Aug  2 15:18:46 2015  Mysql Error 2003: Can't connect to MySQL server on '192.168.65.148' (113) sql: 
Traceback (most recent call last):
  File "../server_base/mysql_handle.py", line 74, in connect_MySQL
    self.mysql_db, charset='utf8')
  File "/usr/lib/python2.7/dist-packages/MySQLdb/__init__.py", line 81, in Connect
    return Connection(*args, **kwargs)
  File "/usr/lib/python2.7/dist-packages/MySQLdb/connections.py", line 187, in __init__
    super(Connection, self).__init__(*args, **kwargs2)
OperationalError: (2003, "Can't connect to MySQL server on '192.168.65.148' (113)")
Sun Aug  2 15:19:19 2015  Sun Aug  2 15:19:19 2015  Mysql Error 2003: Can't connect to MySQL server on '192.168.65.148' (113) sql: 
Traceback (most recent call last):
  File "../server_base/mysql_handle.py", line 74, in connect_MySQL
    self.mysql_db, charset='utf8')
  File "/usr/lib/python2.7/dist-packages/MySQLdb/__init__.py", line 81, in Connect
    return Connection(*args, **kwargs)
  File "/usr/lib/python2.7/dist-packages/MySQLdb/connections.py", line 187, in __init__
    super(Connection, self).__init__(*args, **kwargs2)
OperationalError: (2003, "Can't connect to MySQL server on '192.168.65.148' (113)")
Sun Aug  2 15:19:52 2015  Sun Aug  2 15:19:52 2015  Mysql Error 2003: Can't connect to MySQL server on '192.168.65.148' (113) sql: 
Traceback (most recent call last):
  File "../server_base/mysql_handle.py", line 74, in connect_MySQL
    self.mysql_db, charset='utf8')
  File "/usr/lib/python2.7/dist-packages/MySQLdb/__init__.py", line 81, in Connect
    return Connection(*args, **kwargs)
  File "/usr/lib/python2.7/dist-packages/MySQLdb/connections.py", line 187, in __init__
    super(Connection, self).__init__(*args, **kwargs2)
OperationalError: (2003, "Can't connect to MySQL server on '192.168.65.148' (113)")
Sun Aug  2 15:20:25 2015  Sun Aug  2 15:20:25 2015  Mysql Error 2003: Can't connect to MySQL server on '192.168.65.148' (113) sql: 
Traceback (most recent call last):
  File "../server_base/mysql_handle.py", line 74, in connect_MySQL
    self.mysql_db, charset='utf8')
  File "/usr/lib/python2.7/dist-packages/MySQLdb/__init__.py", line 81, in Connect
    return Connection(*args, **kwargs)
  File "/usr/lib/python2.7/dist-packages/MySQLdb/connections.py", line 187, in __init__
    super(Connection, self).__init__(*args, **kwargs2)
OperationalError: (2003, "Can't connect to MySQL server on '192.168.65.148' (113)")
Sun Aug  2 15:20:58 2015  Sun Aug  2 15:20:58 2015  Mysql Error 2003: Can't connect to MySQL server on '192.168.65.148' (113) sql: 
Traceback (most recent call last):
  File "../server_base/mysql_handle.py", line 74, in connect_MySQL
    self.mysql_db, charset='utf8')
  File "/usr/lib/python2.7/dist-packages/MySQLdb/__init__.py", line 81, in Connect
    return Connection(*args, **kwargs)
  File "/usr/lib/python2.7/dist-packages/MySQLdb/connections.py", line 187, in __init__
    super(Connection, self).__init__(*args, **kwargs2)
OperationalError: (2003, "Can't connect to MySQL server on '192.168.65.148' (113)")
Sun Aug  2 15:21:31 2015  Sun Aug  2 15:21:31 2015  Mysql Error 2003: Can't connect to MySQL server on '192.168.65.148' (113) sql: 
Traceback (most recent call last):
  File "../server_base/mysql_handle.py", line 74, in connect_MySQL
    self.mysql_db, charset='utf8')
  File "/usr/lib/python2.7/dist-packages/MySQLdb/__init__.py", line 81, in Connect
    return Connection(*args, **kwargs)
  File "/usr/lib/python2.7/dist-packages/MySQLdb/connections.py", line 187, in __init__
    super(Connection, self).__init__(*args, **kwargs2)
OperationalError: (2003, "Can't connect to MySQL server on '192.168.65.148' (113)")
Sun Aug  2 15:22:04 2015  Sun Aug  2 15:22:04 2015  Mysql Error 2003: Can't connect to MySQL server on '192.168.65.148' (113) sql: 
Traceback (most recent call last):
  File "../server_base/mysql_handle.py", line 74, in connect_MySQL
    self.mysql_db, charset='utf8')
  File "/usr/lib/python2.7/dist-packages/MySQLdb/__init__.py", line 81, in Connect
    return Connection(*args, **kwargs)
  File "/usr/lib/python2.7/dist-packages/MySQLdb/connections.py", line 187, in __init__
    super(Connection, self).__init__(*args, **kwargs2)
OperationalError: (2003, "Can't connect to MySQL server on '192.168.65.148' (113)")
Sun Aug  2 15:22:37 2015  Sun Aug  2 15:22:37 2015  Mysql Error 2003: Can't connect to MySQL server on '192.168.65.148' (113) sql: 
Traceback (most recent call last):
  File "../server_base/mysql_handle.py", line 74, in connect_MySQL
    self.mysql_db, charset='utf8')
  File "/usr/lib/python2.7/dist-packages/MySQLdb/__init__.py", line 81, in Connect
    return Connection(*args, **kwargs)
  File "/usr/lib/python2.7/dist-packages/MySQLdb/connections.py", line 187, in __init__
    super(Connection, self).__init__(*args, **kwargs2)
OperationalError: (2003, "Can't connect to MySQL server on '192.168.65.148' (113)")
Sun Aug  2 15:23:10 2015  Sun Aug  2 15:23:10 2015  Mysql Error 2003: Can't connect to MySQL server on '192.168.65.148' (113) sql: 
Traceback (most recent call last):
  File "../server_base/mysql_handle.py", line 74, in connect_MySQL
    self.mysql_db, charset='utf8')
  File "/usr/lib/python2.7/dist-packages/MySQLdb/__init__.py", line 81, in Connect
    return Connection(*args, **kwargs)
  File "/usr/lib/python2.7/dist-packages/MySQLdb/connections.py", line 187, in __init__
    super(Connection, self).__init__(*args, **kwargs2)
OperationalError: (2003, "Can't connect to MySQL server on '192.168.65.148' (113)")
Sun Aug  2 15:23:43 2015  Sun Aug  2 15:23:43 2015  Mysql Error 2003: Can't connect to MySQL server on '192.168.65.148' (113) sql: 
Traceback (most recent call last):
  File "../server_base/mysql_handle.py", line 74, in connect_MySQL
    self.mysql_db, charset='utf8')
  File "/usr/lib/python2.7/dist-packages/MySQLdb/__init__.py", line 81, in Connect
    return Connection(*args, **kwargs)
  File "/usr/lib/python2.7/dist-packages/MySQLdb/connections.py", line 187, in __init__
    super(Connection, self).__init__(*args, **kwargs2)
OperationalError: (2003, "Can't connect to MySQL server on '192.168.65.148' (113)")
Sun Aug  2 15:24:16 2015  Sun Aug  2 15:24:16 2015  Mysql Error 2003: Can't connect to MySQL server on '192.168.65.148' (113) sql: 
Traceback (most recent call last):
  File "../server_base/mysql_handle.py", line 74, in connect_MySQL
    self.mysql_db, charset='utf8')
  File "/usr/lib/python2.7/dist-packages/MySQLdb/__init__.py", line 81, in Connect
    return Connection(*args, **kwargs)
  File "/usr/lib/python2.7/dist-packages/MySQLdb/connections.py", line 187, in __init__
    super(Connection, self).__init__(*args, **kwargs2)
OperationalError: (2003, "Can't connect to MySQL server on '192.168.65.148' (113)")
Sun Aug  2 16:35:32 2015  Sun Aug  2 16:35:32 2015  Mysql Error 2003: Can't connect to MySQL server on '192.168.65.148' (101) sql: 
Traceback (most recent call last):
  File "../server_base/mysql_handle.py", line 74, in connect_MySQL
    self.mysql_db, charset='utf8')
  File "/usr/lib/python2.7/dist-packages/MySQLdb/__init__.py", line 81, in Connect
    return Connection(*args, **kwargs)
  File "/usr/lib/python2.7/dist-packages/MySQLdb/connections.py", line 187, in __init__
    super(Connection, self).__init__(*args, **kwargs2)
OperationalError: (2003, "Can't connect to MySQL server on '192.168.65.148' (101)")
